2025-05-29 16:01:02,375 INFO    MainThread:11368 [wandb_setup.py:_flush():76] Current SDK version is 0.15.10
2025-05-29 16:01:02,375 INFO    MainThread:11368 [wandb_setup.py:_flush():76] Configure stats pid to 11368
2025-05-29 16:01:02,375 INFO    MainThread:11368 [wandb_setup.py:_flush():76] Loading settings from C:\Users\HanlinWang\.config\wandb\settings
2025-05-29 16:01:02,375 INFO    MainThread:11368 [wandb_setup.py:_flush():76] Loading settings from D:\github\Opt\main\wandb\settings
2025-05-29 16:01:02,375 INFO    MainThread:11368 [wandb_setup.py:_flush():76] Loading settings from environment variables: {}
2025-05-29 16:01:02,375 INFO    MainThread:11368 [wandb_setup.py:_flush():76] Applying setup settings: {'_disable_service': False}
2025-05-29 16:01:02,375 INFO    MainThread:11368 [wandb_setup.py:_flush():76] Inferring run settings from compute environment: {'program_relpath': 'main.py', 'program': 'D:\\github\\Opt\\main\\main.py'}
2025-05-29 16:01:02,375 INFO    MainThread:11368 [wandb_init.py:_log_setup():524] Logging user logs to D:\github\Opt\main\wandb\run-20250529_160102-z6qzag4r\logs\debug.log
2025-05-29 16:01:02,375 INFO    MainThread:11368 [wandb_init.py:_log_setup():525] Logging internal logs to D:\github\Opt\main\wandb\run-20250529_160102-z6qzag4r\logs\debug-internal.log
2025-05-29 16:01:02,375 INFO    MainThread:11368 [wandb_init.py:init():564] calling init triggers
2025-05-29 16:01:02,375 INFO    MainThread:11368 [wandb_init.py:init():571] wandb.init called with sweep_config: {}
config: {'original_data_path': 'sub_ratings.csv', 'test_data_path': 'test_row.csv', 'num_users': 50, 'num_items': 50, 'user_retention_config': [0.05, 0.4, 0.8, 0.15, 0.2, 0.4, 0.3, 0.1, 0.2, 0.5, 0.0, 0.1], 'model_name': 'MF', 'embedding_dim': 20, 'epochs_per_iteration': 15, 'batch_size': 25, 'test_batch_size': 10, 'learning_rate': 0.005, 'checkpoint_interval': 5, 'checkpoint_dir_base': 'checkpoints_iter', 'gradient_log_dir_base': 'gradient_logs_iter', 'active_learning_strategy': 'TracInCP', 'task_type': 'regression', 'num_collection_points': 50, 'output_visualization_dir': 'visualizations_iter', 'num_iterations': 10, 'wandb_project': 'tracin_active_learning_v4', 'wandb_entity': None, 'disable_wandb': False, 'seed': 42}
2025-05-29 16:01:02,375 INFO    MainThread:11368 [wandb_init.py:init():614] starting backend
2025-05-29 16:01:02,375 INFO    MainThread:11368 [wandb_init.py:init():618] setting up manager
2025-05-29 16:01:02,375 INFO    MainThread:11368 [backend.py:_multiprocessing_setup():105] multiprocessing start_methods=spawn, using: spawn
2025-05-29 16:01:02,378 INFO    MainThread:11368 [wandb_init.py:init():624] backend started and connected
2025-05-29 16:01:02,378 INFO    MainThread:11368 [wandb_init.py:init():715] updated telemetry
2025-05-29 16:01:02,378 INFO    MainThread:11368 [wandb_init.py:init():748] communicating run to backend with 90.0 second timeout
2025-05-29 16:01:03,487 INFO    Thread-5  :11368 [retry.py:__call__():172] Retry attempt failed:
Traceback (most recent call last):
  File "D:\anaconda\envs\agent3\lib\site-packages\urllib3\connectionpool.py", line 711, in urlopen
    self._prepare_proxy(conn)
  File "D:\anaconda\envs\agent3\lib\site-packages\urllib3\connectionpool.py", line 1007, in _prepare_proxy
    conn.connect()
  File "D:\anaconda\envs\agent3\lib\site-packages\urllib3\connection.py", line 419, in connect
    self.sock = ssl_wrap_socket(
  File "D:\anaconda\envs\agent3\lib\site-packages\urllib3\util\ssl_.py", line 449, in ssl_wrap_socket
    ssl_sock = _ssl_wrap_socket_impl(
  File "D:\anaconda\envs\agent3\lib\site-packages\urllib3\util\ssl_.py", line 493, in _ssl_wrap_socket_impl
    return ssl_context.wrap_socket(sock, server_hostname=server_hostname)
  File "D:\anaconda\envs\agent3\lib\ssl.py", line 501, in wrap_socket
    return self.sslsocket_class._create(
  File "D:\anaconda\envs\agent3\lib\ssl.py", line 1074, in _create
    self.do_handshake()
  File "D:\anaconda\envs\agent3\lib\ssl.py", line 1343, in do_handshake
    self._sslobj.do_handshake()
ssl.SSLZeroReturnError: TLS/SSL connection has been closed (EOF) (_ssl.c:1133)

During handling of the above exception, another exception occurred:

Traceback (most recent call last):
  File "D:\anaconda\envs\agent3\lib\site-packages\requests\adapters.py", line 667, in send
    resp = conn.urlopen(
  File "D:\anaconda\envs\agent3\lib\site-packages\urllib3\connectionpool.py", line 798, in urlopen
    retries = retries.increment(
  File "D:\anaconda\envs\agent3\lib\site-packages\urllib3\util\retry.py", line 592, in increment
    raise MaxRetryError(_pool, url, error or ResponseError(cause))
urllib3.exceptions.MaxRetryError: HTTPSConnectionPool(host='api.wandb.ai', port=443): Max retries exceeded with url: /graphql (Caused by SSLError(SSLZeroReturnError(6, 'TLS/SSL connection has been closed (EOF) (_ssl.c:1133)')))

During handling of the above exception, another exception occurred:

Traceback (most recent call last):
  File "D:\anaconda\envs\agent3\lib\site-packages\wandb\sdk\lib\retry.py", line 131, in __call__
    result = self._call_fn(*args, **kwargs)
  File "D:\anaconda\envs\agent3\lib\site-packages\wandb\sdk\internal\internal_api.py", line 358, in execute
    return self.client.execute(*args, **kwargs)  # type: ignore
  File "D:\anaconda\envs\agent3\lib\site-packages\wandb\vendor\gql-0.2.0\wandb_gql\client.py", line 52, in execute
    result = self._get_result(document, *args, **kwargs)
  File "D:\anaconda\envs\agent3\lib\site-packages\wandb\vendor\gql-0.2.0\wandb_gql\client.py", line 60, in _get_result
    return self.transport.execute(document, *args, **kwargs)
  File "D:\anaconda\envs\agent3\lib\site-packages\wandb\sdk\lib\gql_request.py", line 55, in execute
    request = self.session.post(self.url, **post_args)
  File "D:\anaconda\envs\agent3\lib\site-packages\requests\sessions.py", line 637, in post
    return self.request("POST", url, data=data, json=json, **kwargs)
  File "D:\anaconda\envs\agent3\lib\site-packages\requests\sessions.py", line 589, in request
    resp = self.send(prep, **send_kwargs)
  File "D:\anaconda\envs\agent3\lib\site-packages\requests\sessions.py", line 703, in send
    r = adapter.send(request, **kwargs)
  File "D:\anaconda\envs\agent3\lib\site-packages\requests\adapters.py", line 698, in send
    raise SSLError(e, request=request)
requests.exceptions.SSLError: HTTPSConnectionPool(host='api.wandb.ai', port=443): Max retries exceeded with url: /graphql (Caused by SSLError(SSLZeroReturnError(6, 'TLS/SSL connection has been closed (EOF) (_ssl.c:1133)')))
2025-05-29 16:01:44,877 INFO    MainThread:11368 [wandb_run.py:_on_init():2220] communicating current version
2025-05-29 16:01:45,331 INFO    MainThread:11368 [wandb_run.py:_on_init():2229] got version response upgrade_message: "wandb version 0.19.11 is available!  To upgrade, please run:\n $ pip install wandb --upgrade"

2025-05-29 16:01:45,331 INFO    MainThread:11368 [wandb_init.py:init():799] starting run threads in backend
2025-05-29 16:01:50,707 INFO    MainThread:11368 [wandb_run.py:_console_start():2199] atexit reg
2025-05-29 16:01:50,707 INFO    MainThread:11368 [wandb_run.py:_redirect():2054] redirect: wrap_raw
2025-05-29 16:01:50,707 INFO    MainThread:11368 [wandb_run.py:_redirect():2119] Wrapping output streams.
2025-05-29 16:01:50,707 INFO    MainThread:11368 [wandb_run.py:_redirect():2144] Redirects installed.
2025-05-29 16:01:50,707 INFO    MainThread:11368 [wandb_init.py:init():840] run started, returning control to user process
2025-05-29 16:03:29,932 INFO    MainThread:11368 [wandb_run.py:_finish():1934] finishing run 939531372-south-china-university-of-technology/tracin_active_learning_v4/z6qzag4r
2025-05-29 16:03:29,932 INFO    MainThread:11368 [wandb_run.py:_atexit_cleanup():2168] got exitcode: 0
2025-05-29 16:03:29,932 INFO    MainThread:11368 [wandb_run.py:_restore():2151] restore
2025-05-29 16:03:29,932 INFO    MainThread:11368 [wandb_run.py:_restore():2157] restore done
2025-05-29 16:04:34,921 INFO    MainThread:11368 [wandb_run.py:_footer_history_summary_info():3557] rendering history
2025-05-29 16:04:34,922 INFO    MainThread:11368 [wandb_run.py:_footer_history_summary_info():3589] rendering summary
2025-05-29 16:04:34,926 INFO    MainThread:11368 [wandb_run.py:_footer_sync_info():3516] logging synced files
